{"author":{"id":"6a7a78a8548b3394fee6e2e4fa0078b3291db6beebc8c87fc6b7fa59d6900d79"},"ops":[{"type":1,"timestamp":1595698637,"nonce":"OV6DgqCN7+a1OXJffC0mLJYqZA0=","metadata":{"github-id":"MDU6SXNzdWU2NjU2MjUwODM=","github-url":"https://github.com/svpcom/wfb-ng/issues/62","origin":"github"},"title":"make deb issue","message":"I receive this error when trying to 'make deb' on Parrot OS: \n\n\"dh: error: unable to load addon python3: Can't locate Debian/Debhelper/Sequence/python3.pm\"\n\ndoes anyone know what the cause is and how to rectify it? Below is the relevant output. Thanks:\n\n\nmake[1]: Entering directory '/home/g/wifibroadcast/deb_dist/wifibroadcast-20.7.24.69434'\ndh clean --with python3 --buildsystem=python_distutils\ndh: warning: Compatibility levels before 10 are deprecated (level 7 in use)\ndh: error: unable to load addon python3: Can't locate Debian/Debhelper/Sequence/python3.pm in @INC (you may need to install the Debian::Debhelper::Sequence::python3 module) (@INC contains: /etc/perl /usr/local/lib/x86_64-linux-gnu/perl/5.30.0 /usr/local/share/perl/5.30.0 /usr/lib/x86_64-linux-gnu/perl5/5.30 /usr/share/perl5 /usr/lib/x86_64-linux-gnu/perl/5.30 /usr/share/perl/5.30 /usr/local/lib/site_perl /usr/lib/x86_64-linux-gnu/perl-base) at (eval 3) line 1.\nBEGIN failed--compilation aborted at (eval 3) line 1.\n\nmake[1]: *** [debian/rules:7: clean] Error 255\nmake[1]: Leaving directory '/home/g/wifibroadcast/deb_dist/wifibroadcast-20.7.24.69434'\ndpkg-buildpackage: error: fakeroot debian/rules clean subprocess returned exit status 2\nTraceback (most recent call last):\n  File \"./setup.py\", line 62, in \u003cmodule\u003e\n    setup(\n  File \"/home/g/wifibroadcast/env/lib/python3.8/site-packages/setuptools/__init__.py\", line 165, in setup\n    return distutils.core.setup(**attrs)\n  File \"/usr/lib/python3.8/distutils/core.py\", line 148, in setup\n    dist.run_commands()\n  File \"/usr/lib/python3.8/distutils/dist.py\", line 966, in run_commands\n    self.run_command(cmd)\n  File \"/usr/lib/python3.8/distutils/dist.py\", line 985, in run_command\n    cmd_obj.run()\n  File \"/home/g/wifibroadcast/env/lib/python3.8/site-packages/stdeb/command/bdist_deb.py\", line 33, in run\n    self.run_command('sdist_dsc')\n  File \"/usr/lib/python3.8/distutils/cmd.py\", line 313, in run_command\n    self.distribution.run_command(command)\n  File \"/usr/lib/python3.8/distutils/dist.py\", line 985, in run_command\n    cmd_obj.run()\n  File \"/home/g/wifibroadcast/env/lib/python3.8/site-packages/stdeb/command/sdist_dsc.py\", line 135, in run\n    build_dsc(debinfo,\n  File \"/home/g/wifibroadcast/env/lib/python3.8/site-packages/stdeb/util.py\", line 1468, in build_dsc\n    dpkg_buildpackage(*args, cwd=fullpath_repackaged_dirname)\n  File \"/home/g/wifibroadcast/env/lib/python3.8/site-packages/stdeb/util.py\", line 534, in dpkg_buildpackage\n    process_command(args, cwd=cwd)\n  File \"/home/g/wifibroadcast/env/lib/python3.8/site-packages/stdeb/util.py\", line 201, in process_command\n    check_call(args, cwd=cwd)\n  File \"/home/g/wifibroadcast/env/lib/python3.8/site-packages/stdeb/util.py\", line 46, in check_call\n    raise CalledProcessError(retcode)\nstdeb.util.CalledProcessError: 2\nmake: *** [Makefile:52: deb] Error 1","files":null}]}