{"author":{"id":"c0aec0e9db69e0cb495b53bfaa4b5d5ec2018ebd15ca1e4c55e9334cba2de8ad"},"ops":[{"type":1,"timestamp":1621995775,"nonce":"4HLrdZv7ie3wa1xKKhShDkiR9RY=","metadata":{"github-id":"MDU6SXNzdWU5MDE2NDQyNTY=","github-url":"https://github.com/svpcom/wfb-ng/issues/136","origin":"github"},"title":"Installation fails on ubuntu 20.04 with python3","message":"**Describe the bug**\nInstallation fails on ubuntu Focal (20.04).\n\n**To Reproduce**\nSteps to reproduce the behavior:\nInstallation steps until executing make deb.\n\n**Screenshots**\nremoving 'wifibroadcast-trunk' (and everything under it)\ndpkg-buildpackage: warning:     debian/changelog(l1): version 'trunk-1' is invalid: version number does not start with digit\nLINE: wifibroadcast (trunk-1) unstable; urgency=low\ndpkg-buildpackage: info: source package wifibroadcast\ndpkg-buildpackage: info: source version unknown\ndpkg-buildpackage: error: version number does not start with digit\nTraceback (most recent call last):\n  File \"./setup.py\", line 62, in \u003cmodule\u003e\n    setup(\n  File \"/home/ubuntu/develop/wifibroadcast/env/lib/python3.8/site-packages/setuptools/__init__.py\", line 162, in setup\n    return distutils.core.setup(**attrs)\n  File \"/usr/lib/python3.8/distutils/core.py\", line 148, in setup\n    dist.run_commands()\n  File \"/usr/lib/python3.8/distutils/dist.py\", line 966, in run_commands\n    self.run_command(cmd)\n  File \"/usr/lib/python3.8/distutils/dist.py\", line 985, in run_command\n    cmd_obj.run()\n  File \"/home/ubuntu/develop/wifibroadcast/env/lib/python3.8/site-packages/stdeb/command/bdist_deb.py\", line 34, in run\n    self.run_command('sdist_dsc')\n  File \"/usr/lib/python3.8/distutils/cmd.py\", line 313, in run_command\n    self.distribution.run_command(command)\n  File \"/usr/lib/python3.8/distutils/dist.py\", line 985, in run_command\n    cmd_obj.run()\n  File \"/home/ubuntu/develop/wifibroadcast/env/lib/python3.8/site-packages/stdeb/command/sdist_dsc.py\", line 137, in run\n    build_dsc(debinfo,\n  File \"/home/ubuntu/develop/wifibroadcast/env/lib/python3.8/site-packages/stdeb/util.py\", line 1569, in build_dsc\n    dpkg_buildpackage(*args, cwd=fullpath_repackaged_dirname)\n  File \"/home/ubuntu/develop/wifibroadcast/env/lib/python3.8/site-packages/stdeb/util.py\", line 585, in dpkg_buildpackage\n    process_command(args, cwd=cwd)\n  File \"/home/ubuntu/develop/wifibroadcast/env/lib/python3.8/site-packages/stdeb/util.py\", line 226, in process_command\n    check_call(args, cwd=cwd)\n  File \"/home/ubuntu/develop/wifibroadcast/env/lib/python3.8/site-packages/stdeb/util.py\", line 59, in check_call\n    raise CalledProcessError(retcode)\nstdeb.util.CalledProcessError: 2\nmake: *** [Makefile:53: deb] Error 1\n\n**Your setup (please complete the following information):**\n - Ubuntu 20.04\n - Hardware: Rpi 4","files":null}]}