{"author":{"id":"f0897728795d89e2afbd0456bc5a43f6d6359e38f8d47220345410407767d212"},"ops":[{"type":3,"timestamp":1545313512,"nonce":"R+ln3eG7VmjoWwcMhezxvUz7OKc=","metadata":{"github-id":"MDEyOklzc3VlQ29tbWVudDQ0OTAwMzkyMQ==","github-url":"https://github.com/svpcom/wfb-ng/issues/20#issuecomment-449003921"},"message":"@svpcom \nThat's cool! Sorry for being offline so long, I didn't have the time available.\nI'll try it right now!","files":null},{"type":3,"timestamp":1545564739,"nonce":"ixjjr2H+hbJlRiPxhw+wSohwhb8=","metadata":{"github-id":"MDEyOklzc3VlQ29tbWVudDQ0OTYzMDM2Ng==","github-url":"https://github.com/svpcom/wfb-ng/issues/20#issuecomment-449630366"},"message":"@svpcom I don't know if i should create a new issue or post in this one.\nI am not sure if I installed it the right way, I used _EZ-Wifibroadcast_'s image, I extracted the contents of `wifibroadcast-18.12.17.57289.linux-raspberry_pi.tar.gz` and then I copied `usr`, `lib` and `etc` to `/`. But, when I run `wfb-cli`, it gives me this error:\n```\nTraceback (most recent call last):\n  File \"/usr/bin/wfb-cli\", line 6, in \u003cmodule\u003e\n    from pkg_resources import load_entry_point\n  File \"/usr/lib/python2.7/dist-packages/pkg_resources.py\", line 2876, in \u003cmodule\u003e\n    working_set = WorkingSet._build_master()\n  File \"/usr/lib/python2.7/dist-packages/pkg_resources.py\", line 449, in _build_master\n    ws.require(__requires__)\n  File \"/usr/lib/python2.7/dist-packages/pkg_resources.py\", line 745, in require\n    needed = self.resolve(parse_requirements(requirements))\n  File \"/usr/lib/python2.7/dist-packages/pkg_resources.py\", line 639, in resolve\n    raise DistributionNotFound(req)\npkg_resources.DistributionNotFound: wifibroadcast==18.12.17.57289\n```\nAnd I don't know how to fix it.","files":null}]}